Workbook

Sheet Summary
A1: Top Travel Insider: listicle content plan with pillars & clusters (SE Ranking US+UK, Oct 2026)
B3: All posts | C3: Wave 1 | D3: Wave 2 | E3: Wave 3 | F3: Wave 4
A4: Posts | B4: =COUNTIFS('Post Plan'!$A$2:$A$348,">0") -> 347 | C4: =COUNTIFS('Post Plan'!$A$2:$A$348,">0",'Post Plan'!$B$2:$B$348,"Wave 1") -> 100 | D4: =COUNTIFS('Post Plan'!$A$2:$A$348,">0",'Post Plan'!$B$2:$B$348,"Wave 2") -> 100 | E4: =COUNTIFS('Post Plan'!$A$2:$A$348,">0",'Post Plan'!$B$2:$B$348,"Wave 3") -> 100 | F4: =COUNTIFS('Post Plan'!$A$2:$A$348,">0",'Post Plan'!$B$2:$B$348,"Wave 4") -> 47
A5: Food & drink posts | B5: =COUNTIFS('Post Plan'!$E$2:$E$348,"Food & drink") -> 218 | C5: =COUNTIFS('Post Plan'!$E$2:$E$348,"Food & drink",'Post Plan'!$B$2:$B$348,"Wave 1") -> 60 | D5: =COUNTIFS('Post Plan'!$E$2:$E$348,"Food & drink",'Post Plan'!$B$2:$B$348,"Wave 2") -> 62 | E5: =COUNTIFS('Post Plan'!$E$2:$E$348,"Food & drink",'Post Plan'!$B$2:$B$348,"Wave 3") -> 67 | F5: =COUNTIFS('Post Plan'!$E$2:$E$348,"Food & drink",'Post Plan'!$B$2:$B$348,"Wave 4") -> 29
A6: Place posts | B6: =COUNTIFS('Post Plan'!$E$2:$E$348,"Place") -> 129 | C6: =COUNTIFS('Post Plan'!$E$2:$E$348,"Place",'Post Plan'!$B$2:$B$348,"Wave 1") -> 40 | D6: =COUNTIFS('Post Plan'!$E$2:$E$348,"Place",'Post Plan'!$B$2:$B$348,"Wave 2") -> 38 | E6: =COUNTIFS('Post Plan'!$E$2:$E$348,"Place",'Post Plan'!$B$2:$B$348,"Wave 3") -> 33 | F6: =COUNTIFS('Post Plan'!$E$2:$E$348,"Place",'Post Plan'!$B$2:$B$348,"Wave 4") -> 18
A7: Quick wins (KD 10 or under) | B7: =COUNTIFS('Post Plan'!$P$2:$P$348,"Quick win") -> 195 | C7: =COUNTIFS('Post Plan'!$P$2:$P$348,"Quick win",'Post Plan'!$B$2:$B$348,"Wave 1") -> 75 | D7: =COUNTIFS('Post Plan'!$P$2:$P$348,"Quick win",'Post Plan'!$B$2:$B$348,"Wave 2") -> 49 | E7: =COUNTIFS('Post Plan'!$P$2:$P$348,"Quick win",'Post Plan'!$B$2:$B$348,"Wave 3") -> 61 | F7: =COUNTIFS('Post Plan'!$P$2:$P$348,"Quick win",'Post Plan'!$B$2:$B$348,"Wave 4") -> 10
A8: Monthly volume (US+UK) | B8: =SUMIFS('Post Plan'!$M$2:$M$348,'Post Plan'!$A$2:$A$348,">0") -> 172180 | C8: =SUMIFS('Post Plan'!$M$2:$M$348,'Post Plan'!$A$2:$A$348,">0",'Post Plan'!$B$2:$B$348,"Wave 1") -> 91160 | D8: =SUMIFS('Post Plan'!$M$2:$M$348,'Post Plan'!$A$2:$A$348,">0",'Post Plan'!$B$2:$B$348,"Wave 2") -> 47850 | E8: =SUMIFS('Post Plan'!$M$2:$M$348,'Post Plan'!$A$2:$A$348,">0",'Post Plan'!$B$2:$B$348,"Wave 3") -> 23480 | F8: =SUMIFS('Post Plan'!$M$2:$M$348,'Post Plan'!$A$2:$A$348,">0",'Post Plan'!$B$2:$B$348,"Wave 4") -> 9690
A9: Average weighted KD | B9: =AVERAGEIFS('Post Plan'!$N$2:$N$348,'Post Plan'!$A$2:$A$348,">0") -> 10.983573 | C9: =AVERAGEIFS('Post Plan'!$N$2:$N$348,'Post Plan'!$A$2:$A$348,">0",'Post Plan'!$B$2:$B$348,"Wave 1") -> 8.554 | D9: =AVERAGEIFS('Post Plan'!$N$2:$N$348,'Post Plan'!$A$2:$A$348,">0",'Post Plan'!$B$2:$B$348,"Wave 2") -> 10.969 | E9: =AVERAGEIFS('Post Plan'!$N$2:$N$348,'Post Plan'!$A$2:$A$348,">0",'Post Plan'!$B$2:$B$348,"Wave 3") -> 10.907 | F9: =AVERAGEIFS('Post Plan'!$N$2:$N$348,'Post Plan'!$A$2:$A$348,">0",'Post Plan'!$B$2:$B$348,"Wave 4") -> 16.346809
A10: Posts with a data flag | B10: =COUNTIFS('Post Plan'!$U$2:$U$348,"?*") -> 40 | C10: =COUNTIFS('Post Plan'!$U$2:$U$348,"?*",'Post Plan'!$B$2:$B$348,"Wave 1") -> 21 | D10: =COUNTIFS('Post Plan'!$U$2:$U$348,"?*",'Post Plan'!$B$2:$B$348,"Wave 2") -> 7 | E10: =COUNTIFS('Post Plan'!$U$2:$U$348,"?*",'Post Plan'!$B$2:$B$348,"Wave 3") -> 2 | F10: =COUNTIFS('Post Plan'!$U$2:$U$348,"?*",'Post Plan'!$B$2:$B$348,"Wave 4") -> 10
A11: Published | B11: =COUNTIFS('Post Plan'!$V$2:$V$348,"Published") -> 0 | C11: =COUNTIFS('Post Plan'!$V$2:$V$348,"Published",'Post Plan'!$B$2:$B$348,"Wave 1") -> 0 | D11: =COUNTIFS('Post Plan'!$V$2:$V$348,"Published",'Post Plan'!$B$2:$B$348,"Wave 2") -> 0 | E11: =COUNTIFS('Post Plan'!$V$2:$V$348,"Published",'Post Plan'!$B$2:$B$348,"Wave 3") -> 0 | F11: =COUNTIFS('Post Plan'!$V$2:$V$348,"Published",'Post Plan'!$B$2:$B$348,"Wave 4") -> 0
A13: Pillars | B13: =COUNTA('Content Plan (Pillars)'!B2:B68) -> 67
A14: City hubs | B14: =COUNTIF('Content Plan (Pillars)'!C2:C68,"City hub") -> 40
A15: Country hubs | B15: =COUNTIF('Content Plan (Pillars)'!C2:C68,"Country hub") -> 22
A16: Region hubs | B16: =COUNTIF('Content Plan (Pillars)'!C2:C68,"Region hub") -> 5
A17: Built by upgrading an existing post | B17: =COUNTIF('Content Plan (Pillars)'!F2:F68,"Existing*") -> 15
A19: How the plan is structured
A20: Architecture: Region hub > Country hub > City hub > listicle spokes. A place with 3+ spokes gets its own city hub; smaller places roll up to their country hub, or to the region hub if the country has fewer than 3 posts.
A21: Clusters inside each hub: Eat, Drink, Explore nearby (day trips, weekend getaways), See & do, Beaches & islands, Towns, villages & nature. The Cluster Map tab shows every hub's spokes laid out by cluster.
A22: Internal linking: every spoke links up to its hub and across to two siblings (same cluster first). Hubs link down to all spokes and up to their parent hub. The suggested links are in the Post Plan's 'Internal links' column.
A23: Pillar keywords: '[place] travel guide' was measured where possible. Volumes are modest (mostly 100 to 740) because the pillar's job is to concentrate links and topical authority, not to be the main traffic page. Budapest, Prague, Madrid, Nashville and Copenhagen have the best pillar terms.
A24: Existing posts are used as hubs wherever they fit, upgraded rather than rebuilt: the UK post is the parent of the England, Scotland and Wales hubs; the Vietnam post is the parent of Hanoi and Ho Chi Minh City (with Sapa, Hue and Ninh Binh linked under it); the Japan post is the parent of Tokyo, Osaka and Kyoto; USA, Thailand, Portugal and Peru head their country hubs; Edinburgh, London, Tokyo, NYC, Chicago, Amsterdam, Barcelona and Athens are city hubs.
A25: Waves: Wave 1 is ranks 1 to 100, Wave 2 is 101 to 200, Wave 3 is 201 to 300, Wave 4 is the rest. Within a wave, publish spokes for the same hub close together so the hub can go live with links in place.
A26: Scoring is unchanged: only market-keyword rows at KD 40 or under count, Weighted KD is volume-weighted, Winnability = Total volume / (KD + 10), scaled by 0.25 above KD 35 or for cross-market KD mismatches.
A27: Grouping is by topic and place, not by SERP overlap. Before writing pairs that sit close together (e.g. 'Places to Eat' vs 'Foods to Try', or 'Bars' vs 'Rooftop Bars' in the same city), spot-check the SERPs; if the same URLs rank for both, merge them.
A28: Yellow columns are blank for you to fill in (status, writer, dates, URLs). Hub and summary progress counts update automatically from the Status column.

Sheet Batch 1 Briefs
A1: Plan rank | B1: Post title | C1: Suggested slug | D1: Primary keyword | E1: Volume (US+UK) | F1: KD | G1: Hub | H1: Cluster | I1: Search intent | J1: 10 items (verify before writing) | K1: Reserves | L1: Candidate FAQs (confirm vs People Also Ask) | M1: Internal links | N1: Target words | O1: In-article photos | P1: Practical boxes | Q1: FAQs | R1: Writer | S1: Draft due | T1: Facts checked | U1: Photos sourced | V1: Rendered (tti_render.py) | W1: Published URL
A2: 1 | B2: Top 10 Day Trips from Edinburgh | C2: /top-10-day-trips-from-edinburgh/ | D2: day trips from edinburgh | E2: 2210 | F2: 6.3 | G2: Edinburgh | H2: Explore nearby | I2: Planning which places to visit on a one-day return trip from Edinburgh by train, bus, tour or car. | J2: Stirling (castle, Wallace Monument); St Andrews; Loch Lomond & the Trossachs; Falkirk Wheel & The Kelpies; Linlithgow Palace; North Berwick & Tantallon Castle; Rosslyn Chapel & Roslin Glen; Culross & Dunfermline; Melrose & the Scottish Borders abbeys; Glencoe (long day, usually by tour) | K2: Pentland Hills; Glasgow (link to Glasgow hub instead); Loch Ness (long tour day, very common search) | L2: Can you do Loch Ness as a day trip from Edinburgh? | Is Stirling worth a day trip from Edinburgh? | Do you need a car for day trips from Edinburgh? | What is the best day trip from Edinburgh by train? | Can you visit the Highlands in a day from Edinburgh? | Is St Andrews or Stirling better for a day trip? | M2: Edinburgh hub (existing Edinburgh post); https://toptravelinsider.com/top-10-castles-to-visit-in-the-uk-travel-guide/; https://toptravelinsider.com/top-10-historic-places-in-the-uk/; https://toptravelinsider.com/top-10-hidden-gems-in-the-uk/ | N2: 2,500 to 3,000 | O2: 10 | P2: 10 | Q2: 5 to 6 | R2: Claude (draft 1) | T2: Partly | U2: No | V2: No
A3: 2 | B3: Top 10 Places to Eat in Copenhagen | C3: /top-10-places-to-eat-in-copenhagen/ | D3: where to eat in copenhagen | E3: 2210 | F3: 7.8 | G3: Copenhagen | H3: Eat | I3: Choosing where to eat in Copenhagen across budgets: smørrebrød, bakeries, food halls, New Nordic and fine dining. | J3: Torvehallerne food market; Reffen street food (seasonal, check opening); Schønnemann (smørrebrød); Aamanns (smørrebrød); Hart Bageri (bakery); Bæst (pizza, Nørrebro); Kødbyens Fiskebar (Meatpacking District); Barr; Hija de Sanchez (tacos); One fine-dining pick (Alchemist or similar) | K3: Admiralgade 26; Mirabelle; Lille Bakery. Confirm every venue is still trading and its booking policy before writing. | L3: What food is Copenhagen famous for? | Is eating out in Copenhagen expensive? | Do you need to book restaurants in Copenhagen? | Do you tip in Copenhagen? | Where can you eat cheaply in Copenhagen? | What is smørrebrød? | M3: Copenhagen hub (new); Cafes in Copenhagen (#11); Bars in Copenhagen (#18) | N3: 2,500 to 3,000 | O3: 10 | P3: 10 | Q3: 5 to 6 | R3: Claude (draft 1) | T3: No | U3: No | V3: No
A4: 3 | B4: Top 10 Day Trips from Tokyo | C4: /top-10-day-trips-from-tokyo/ | D4: day trips from tokyo | E4: 1630 | F4: 5.9 | G4: Tokyo | H4: Explore nearby | I4: Picking easy one-day trips from Tokyo by train, with how long each takes and whether a pass is worth it. | J4: Kamakura; Hakone; Mount Fuji Five Lakes (Kawaguchiko); Nikko; Yokohama; Kawagoe; Enoshima; Mount Takao; Chichibu; Karuizawa | K4: Kusatsu Onsen (long day); Mito (Kairakuen, seasonal); Sawara | L4: What is the easiest day trip from Tokyo? | Can you see Mount Fuji on a day trip from Tokyo? | Is the JR Pass worth it for day trips from Tokyo? | Is Hakone or Nikko better for a day trip? | How do you get to Kamakura from Tokyo? | Can you do Kyoto as a day trip from Tokyo? | M4: Tokyo hub (existing Tokyo post); Japan hub (existing Japan post); Day Trips from Osaka (#9) | N4: 2,500 to 3,000 | O4: 10 | P4: 10 | Q4: 5 to 6 | R4: Claude (draft 1) | T4: No | U4: No | V4: No
A5: 4 | B5: Top 10 Day Trips from Lisbon | C5: /top-10-day-trips-from-lisbon/ | D5: day trips from lisbon | E5: 1400 | F5: 6 | G5: Lisbon | H5: Explore nearby | I5: Choosing day trips from Lisbon (palaces, beaches, historic towns) and how to reach them without a car. | J5: Sintra; Cascais & Estoril; Évora; Óbidos; Arrábida Natural Park & Setúbal; Nazaré; Tomar; Coimbra; Ericeira; Fátima, Batalha & Alcobaça loop | K5: Cabo da Roca (combine with Sintra); Comporta; Costa da Caparica | L5: Is Sintra worth a day trip from Lisbon? | Can you do Sintra and Cascais in one day? | How do you get from Lisbon to Sintra by train? | Is Porto too far for a day trip from Lisbon? | What is the best beach day trip from Lisbon? | Do you need a car for day trips from Lisbon? | M5: Lisbon hub (new: or the live 'things to do in Lisbon' post if it exists); Places to Eat in Lisbon (#6); Portugal hub (existing Portugal post) | N5: 2,500 to 3,000 | O5: 10 | P5: 10 | Q5: 5 to 6 | R5: Claude (draft 1) | T5: No | U5: No | V5: No
A6: 6 | B6: Top 10 Places to Eat in Lisbon | C6: /top-10-places-to-eat-in-lisbon/ | D6: where to eat in lisbon | E6: 1240 | F6: 6.2 | G6: Lisbon | H6: Eat | I6: Finding the best places to eat in Lisbon by neighbourhood and budget, including pastéis de nata and seafood. | J6: Time Out Market (Mercado da Ribeira); Cervejaria Ramiro (seafood); Pastéis de Belém; Manteigaria (pastéis de nata); Taberna da Rua das Flores; Zé da Mouraria; O Velho Eurico; A Cevicheria; Prado; Sol e Pesca (tinned fish) | K6: Café de São Bento (steak); Belcanto (fine dining); a tasca in Alfama. Verify each is open and how bookings work. | L6: What food is Lisbon famous for? | Where can you get the best pastel de nata in Lisbon? | Is Time Out Market worth it? | Do you need to book restaurants in Lisbon? | Is eating out in Lisbon cheap? | What is a tasca? | M6: Lisbon hub; Day Trips from Lisbon (#4); Portugal hub (existing Portugal post) | N6: 2,500 to 3,000 | O6: 10 | P6: 10 | Q6: 5 to 6 | R6: Claude (draft 1) | T6: No | U6: No | V6: No
A7: 7 | B7: Top 10 Day Trips from London | C7: /top-10-day-trips-from-london/ | D7: best day trips from london | E7: 1330 | F7: 7.4 | G7: London | H7: Explore nearby | I7: Choosing day trips from London by train, with what each place suits and how long to allow. | J7: Oxford; Cambridge; Bath; Windsor; Stonehenge (with Salisbury); Brighton; Canterbury; Seven Sisters & Beachy Head; The Cotswolds; Rye | K7: Whitstable; Leeds Castle; Winchester | L7: What is the best day trip from London by train? | Can you do Stonehenge and Bath in one day from London? | Is Oxford or Cambridge better for a day trip? | Can you visit the Cotswolds in a day without a car? | How far is Brighton from London by train? | Are day tours from London worth it? | M7: London hub (existing London post); https://toptravelinsider.com/top-10-weekend-getaways-uk/; https://toptravelinsider.com/top-10-castles-to-visit-in-the-uk-travel-guide/; https://toptravelinsider.com/top-10-historic-places-in-the-uk/ | N7: 2,500 to 3,000 | O7: 10 | P7: 10 | Q7: 5 to 6 | R7: Claude (draft 1) | T7: No | U7: No | V7: No
A8: 15 | B8: Top 10 Day Trips from Amsterdam | C8: /top-10-day-trips-from-amsterdam/ | D8: best day trips from amsterdam | E8: 1070 | F8: 6 | G8: Amsterdam | H8: Explore nearby | I8: Planning day trips from Amsterdam: windmills, canal towns, Dutch cities and seasonal tulips. | J8: Zaanse Schans; Haarlem; Utrecht; Giethoorn; Volendam & Marken; Edam; Delft; The Hague; Rotterdam; Keukenhof (spring only) or Kinderdijk | K8: Leiden; Alkmaar cheese market (seasonal); Muiderslot | L8: What is the best day trip from Amsterdam? | Is Giethoorn worth a day trip from Amsterdam? | Can you do Zaanse Schans, Volendam and Edam in one day? | When is Keukenhof open? | How do you get to Haarlem from Amsterdam? | Is Rotterdam worth a day trip? | M8: Amsterdam hub (existing Amsterdam post); Europe hub | N8: 2,500 to 3,000 | O8: 10 | P8: 10 | Q8: 5 to 6 | R8: Claude (draft 1) | T8: No | U8: No | V8: No
A9: 16 | B9: Top 10 Places to Eat in Budapest | C9: /top-10-places-to-eat-in-budapest/ | D9: best food in budapest | E9: 1190 | F9: 7.8 | G9: Budapest | H9: Eat | I9: Finding where to eat in Budapest: Hungarian classics, market food, ruin-bar area street food and cafés. | J9: Great Market Hall (Központi Vásárcsarnok); Karaván street food; Gettó Gulyás; Frici Papa; Hungarikum Bisztró; Mazel Tov; Borkonyha; Stand; Bors GasztroBár; New York Café or Gerbeaud (café stop) | K9: Szimpla Sunday farmers' market; Kispiac; a lángos stall. Verify every venue is still trading. | L9: What food is Budapest famous for? | Is eating out in Budapest cheap? | Do you tip in Budapest restaurants? | What is lángos? | Is the Great Market Hall worth visiting? | Where to eat goulash in Budapest? | M9: Budapest hub (new); Bars in Budapest; Cafes in Budapest | N9: 2,500 to 3,000 | O9: 10 | P9: 10 | Q9: 5 to 6 | R9: Claude (draft 1) | T9: No | U9: No | V9: No
A10: 17 | B10: Top 10 Places to Eat in Osaka | C10: /top-10-places-to-eat-in-osaka/ | D10: best food in osaka | E10: 1110 | F10: 6.9 | G10: Osaka | H10: Eat | I10: Finding the best places to eat in Osaka, from street food in Dotonbori to markets and okonomiyaki. | J10: Dotonbori street food; Kuromon Ichiba Market; Shinsekai kushikatsu; Mizuno (okonomiyaki); Hozenji Yokocho; Ura Namba izakayas; Tenjinbashisuji shopping street; Wanaka (takoyaki); Harukoma (sushi); Endo Sushi (Central Fish Market) | K10: Fukushima izakaya area; Rikuro's cheesecake; Kiji (okonomiyaki). Verify opening days and queue norms. | L10: What food is Osaka famous for? | Is Osaka the food capital of Japan? | Where to eat takoyaki in Osaka? | Is Kuromon Market worth it? | Do you need reservations in Osaka? | Is eating out in Osaka cheap? | M10: Osaka hub (new); Japan hub (existing Japan post); Day Trips from Osaka (#9) | N10: 2,500 to 3,000 | O10: 10 | P10: 10 | Q10: 5 to 6 | R10: Claude (draft 1) | T10: No | U10: No | V10: No
A11: 27 | B11: Top 10 Beer Halls & Beer Gardens in Munich | C11: /top-10-beer-halls-beer-gardens-in-munich/ | D11: best beer halls in munich | E11: 1140 | F11: 9.7 | G11: Munich | H11: Drink | I11: Choosing which Munich beer halls and beer gardens to visit, what to order and how they work. | J11: Hofbräuhaus; Augustiner-Keller; Augustiner Bräustuben; Chinesischer Turm (English Garden); Hirschgarten; Löwenbräukeller; Paulaner am Nockherberg; Viktualienmarkt beer garden; Seehaus (English Garden); Weisses Bräuhaus (Schneider) | K11: Andechs Monastery (day trip); Aumeister; Taxisgarten | L11: What is the most famous beer hall in Munich? | Can you bring your own food to Munich beer gardens? | When are Munich beer gardens open? | What is the difference between a beer hall and a beer garden? | Is Hofbräuhaus worth visiting? | What beer should you order in Munich? | M11: Munich hub (new); Bars in Munich; Day Trips from Munich | N11: 2,500 to 3,000 | O11: 10 | P11: 10 | Q11: 5 to 6 | R11: Claude (draft 1) | T11: No | U11: No | V11: No

Sheet Content Standards
A1: Post standard for new Top Travel Insider listicles (from the content review)
A3: Why it changed | B3: The first 20 new posts ran 1,369 to 1,682 words (median 1,423) with only a featured image, against a median of 4,312 words and 4 to 10 images on the older posts. Pages ranking for these searches typically run 2,500 to 4,000 words with a photo per item and practical detail.
A4: Target length | B4: 2,500 to 3,000 useful words. Template minimum raised from 1,200 to 2,000. Word count isn't a ranking factor in itself; completeness is.
A5: Per item (x10) | B5: H2 + 250 to 350 words + one photo + practical box: How to get there / How long to spend / Best time of day / One specific tip.
A6: Photos | B6: Featured image plus 4 to 10 in-article (aim for one per item). Free Unsplash, alt text and credits, checked the same way as featured images. Needs the tti_render.py and images.py extension plus a BLOG_TEMPLATE.md update.
A7: Supporting sections | B7: Suggested plan for 1, 2 or 3 days; where to stay by area; getting around; budget in tiers (shoestring / mid-range / comfortable), never exact prices.
A8: FAQs | B8: 5 or 6 per post (up from 3), taken from questions people actually search: confirm against Google's People Also Ask for the primary keyword.
A9: Fact checking | B9: Transport times, opening seasons, booking rules, venue status and site rules (e.g. Benagil, Blue Eye) checked against official sources. If it can't be confirmed, leave it out rather than guess.
A10: House rules | B10: No em or en dashes. UK spelling. No made-up first-hand stories. Schema as per the template.
A11: Workflow | B11: Every change goes into the Markdown files, then through tti_render.py, then onto the live posts. The same applies to fixing the 20 existing thin posts.
A12: Internal linking | B12: Each post links up to its hub, across to two siblings and to relevant live posts. The hubs link down to every spoke once live. See the Post Plan 'Internal links' column.
A13: Hub upgrades | B13: Existing posts acting as hubs (UK, Vietnam, Japan, USA, Thailand, Portugal, Peru, Edinburgh, London, Tokyo, NYC, Chicago, Amsterdam, Barcelona, Athens) get a short section per cluster linking to the spokes as they publish.

Sheet Content Plan (Pillars)
A1: Pillar rank | B1: Pillar (hub) | C1: Hub type | D1: Region | E1: Parent hub | F1: Pillar status | G1: Suggested pillar title | H1: Pillar keyword | I1: Pillar kw volume (US+UK) | J1: Pillar kw KD | K1: Direct spokes | L1: Eat | M1: Drink | N1: Explore nearby | O1: See & do | P1: Beaches & islands | Q1: Towns, villages & nature | R1: Spoke volume | S1: Spoke winnability | T1: Wave 1 spokes | U1: First spoke rank | V1: Build note | W1: Pillar URL | X1: Owner | Y1: Pillar status (progress) | Z1: Publish date | AA1: Spokes published | AB1: Notes
A2: 1 | B2: England | C2: Country hub | D2: UK | E2: UK | F2: New pillar to create | G2: England Travel Guide: Where to Eat, Drink and Explore | H2: england travel guide | K2: =COUNTIF('Post Plan'!$I$2:$I$348,B2) -> 16 | L2: =COUNTIFS('Post Plan'!$I$2:$I$348,$B2,'Post Plan'!$J$2:$J$348,"Eat") -> 3 | M2: =COUNTIFS('Post Plan'!$I$2:$I$348,$B2,'Post Plan'!$J$2:$J$348,"Drink") -> 2 | N2: =COUNTIFS('Post Plan'!$I$2:$I$348,$B2,'Post Plan'!$J$2:$J$348,"Explore nearby") -> 5 | O2: =COUNTIFS('Post Plan'!$I$2:$I$348,$B2,'Post Plan'!$J$2:$J$348,"See & do") -> 0 | P2: =COUNTIFS('Post Plan'!$I$2:$I$348,$B2,'Post Plan'!$J$2:$J$348,"Beaches & islands") -> 2 | Q2: =COUNTIFS('Post Plan'!$I$2:$I$348,$B2,'Post Plan'!$J$2:$J$348,"Towns, villages & nature") -> 4 | R2: =SUMIF('Post Plan'!$I$2:$I$348,B2,'Post Plan'!$M$2:$M$348) -> 7080 | S2: =SUMIF('Post Plan'!$I$2:$I$348,B2,'Post Plan'!$O$2:$O$348) -> 373.71969 | T2: =COUNTIFS('Post Plan'!$I$2:$I$348,B2,'Post Plan'!$B$2:$B$348,"Wave 1") -> 4 | U2: 53 | V2: Publish after its first 3 to 5 spokes so it launches with links to live content. Links down to child hubs: London. | Y2: Not started | AA2: =COUNTIFS('Post Plan'!$I$2:$I$348,B2,'Post Plan'!$V$2:$V$348,"Published") -> 0
A3: 2 | B3: Spain | C3: Country hub | D3: Europe | E3: Europe | F3: New pillar to create | G3: Spain Travel Guide: Where to Eat, Drink and Explore | H3: spain travel guide | K3: =COUNTIF('Post Plan'!$I$2:$I$348,B3) -> 14 | L3: =COUNTIFS('Post Plan'!$I$2:$I$348,$B3,'Post Plan'!$J$2:$J$348,"Eat") -> 5 | M3: =COUNTIFS('Post Plan'!$I$2:$I$348,$B3,'Post Plan'!$J$2:$J$348,"Drink") -> 1 | N3: =COUNTIFS('Post Plan'!$I$2:$I$348,$B3,'Post Plan'!$J$2:$J$348,"Explore nearby") -> 2 | O3: =COUNTIFS('Post Plan'!$I$2:$I$348,$B3,'Post Plan'!$J$2:$J$348,"See & do") -> 1 | P3: =COUNTIFS('Post Plan'!$I$2:$I$348,$B3,'Post Plan'!$J$2:$J$348,"Beaches & islands") -> 4 | Q3: =COUNTIFS('Post Plan'!$I$2:$I$348,$B3,'Post Plan'!$J$2:$J$348,"Towns, villages & nature") -> 1 | R3: =SUMIF('Post Plan'!$I$2:$I$348,B3,'Post Plan'!$M$2:$M$348) -> 5760 | S3: =SUMIF('Post Plan'!$I$2:$I$348,B3,'Post Plan'!$O$2:$O$348) -> 332.08914 | T3: =COUNTIFS('Post Plan'!$I$2:$I$348,B3,'Post Plan'!$B$2:$B$348,"Wave 1") -> 4 | U3: 21 | V3: Publish after its first 3 to 5 spokes so it launches with links to live content. Links down to child hubs: Barcelona, Madrid. | Y3: Not started | AA3: =COUNTIFS('Post Plan'!$I$2:$I$348,B3,'Post Plan'!$V$2:$V$348,"Published") -> 0
A4: 3 | B4: Europe | C4: Region hub | D4: Europe | E4: Home / Destinations | F4: New pillar to create | G4: Europe Travel Guide: Best Places to Eat, Drink and Explore | H4: europe travel guide | K4: =COUNTIF('Post Plan'!$I$2:$I$348,B4) -> 11 | L4: =COUNTIFS('Post Plan'!$I$2:$I$348,$B4,'Post Plan'!$J$2:$J$348,"Eat") -> 1 | M4: =COUNTIFS('Post Plan'!$I$2:$I$348,$B4,'Post Plan'!$J$2:$J$348,"Drink") -> 0 | N4: =COUNTIFS('Post Plan'!$I$2:$I$348,$B4,'Post Plan'!$J$2:$J$348,"Explore nearby") -> 3 | O4: =COUNTIFS('Post Plan'!$I$2:$I$348,$B4,'Post Plan'!$J$2:$J$348,"See & do") -> 1 | P4: =COUNTIFS('Post Plan'!$I$2:$I$348,$B4,'Post Plan'!$J$2:$J$348,"Beaches & islands") -> 5 | Q4: =COUNTIFS('Post Plan'!$I$2:$I$348,$B4,'Post Plan'!$J$2:$J$348,"Towns, villages & nature") -> 1 | R4: =SUMIF('Post Plan'!$I$2:$I$348,B4,'Post Plan'!$M$2:$M$348) -> 5820 | S4: =SUMIF('Post Plan'!$I$2:$I$348,B4,'Post Plan'!$O$2:$O$348) -> 308.60502 | T4: =COUNTIFS('Post Plan'!$I$2:$I$348,B4,'Post Plan'!$B$2:$B$348,"Wave 1") -> 4 | U4: 23 | V4: Publish after its first 3 to 5 spokes so it launches with links to live content. Links down to child hubs: Amsterdam, Berlin, Budapest, Copenhagen, Croatia, France, Greece, Ireland, Istanbul, Italy, Krakow, Munich, Portugal, Prague, Spain, Switzerland, Vienna. | Y4: Not started | AA4: =COUNTIFS('Post Plan'!$I$2:$I$348,B4,'Post Plan'!$V$2:$V$348,"Published") -> 0
A5: 4 | B5: USA | C5: Country hub | D5: North America | E5: North America | F5: Existing USA post | G5: USA Travel Guide: Where to Eat, Drink and Explore | H5: usa travel guide | K5: =COUNTIF('Post Plan'!$I$2:$I$348,B5) -> 13 | L5: =COUNTIFS('Post Plan'!$I$2:$I$348,$B5,'Post Plan'!$J$2:$J$348,"Eat") -> 6 | M5: =COUNTIFS('Post Plan'!$I$2:$I$348,$B5,'Post Plan'!$J$2:$J$348,"Drink") -> 3 | N5: =COUNTIFS('Post Plan'!$I$2:$I$348,$B5,'Post Plan'!$J$2:$J$348,"Explore nearby") -> 2 | O5: =COUNTIFS('Post Plan'!$I$2:$I$348,$B5,'Post Plan'!$J$2:$J$348,"See & do") -> 0 | P5: =COUNTIFS('Post Plan'!$I$2:$I$348,$B5,'Post Plan'!$J$2:$J$348,"Beaches & islands") -> 1 | Q5: =COUNTIFS('Post Plan'!$I$2:$I$348,$B5,'Post Plan'!$J$2:$J$348,"Towns, villages & nature") -> 1 | R5: =SUMIF('Post Plan'!$I$2:$I$348,B5,'Post Plan'!$M$2:$M$348) -> 7860 | S5: =SUMIF('Post Plan'!$I$2:$I$348,B5,'Post Plan'!$O$2:$O$348) -> 304.28813 | T5: =COUNTIFS('Post Plan'!$I$2:$I$348,B5,'Post Plan'!$B$2:$B$348,"Wave 1") -> 2 | U5: 66 | V5: Upgrade the existing post into a hub: add a section per cluster linking to each spoke. Links down to child hubs: Austin, Charleston, Chicago, Miami, Nashville, New Orleans, New York, San Francisco, Savannah. | Y5: Not started | AA5: =COUNTIFS('Post Plan'!$I$2:$I$348,B5,'Post Plan'!$V$2:$V$348,"Published") -> 0
A6: 5 | B6: Copenhagen | C6: City hub | D6: Europe | E6: Europe | F6: New pillar to create | G6: Copenhagen Travel Guide: Where to Eat, Drink and Explore | H6: copenhagen travel guide | I6: 370 | J6: 18.7 | K6: =COUNTIF('Post Plan'!$I$2:$I$348,B6) -> 4 | L6: =COUNTIFS('Post Plan'!$I$2:$I$348,$B6,'Post Plan'!$J$2:$J$348,"Eat") -> 2 | M6: =COUNTIFS('Post Plan'!$I$2:$I$348,$B6,'Post Plan'!$J$2:$J$348,"Drink") -> 1 | N6: =COUNTIFS('Post Plan'!$I$2:$I$348,$B6,'Post Plan'!$J$2:$J$348,"Explore nearby") -> 1 | O6: =COUNTIFS('Post Plan'!$I$2:$I$348,$B6,'Post Plan'!$J$2:$J$348,"See & do") -> 0 | P6: =COUNTIFS('Post Plan'!$I$2:$I$348,$B6,'Post Plan'!$J$2:$J$348,"Beaches & islands") -> 0 | Q6: =COUNTIFS('Post Plan'!$I$2:$I$348,$B6,'Post Plan'!$J$2:$J$348,"Towns, villages & nature") -> 0 | R6: =SUMIF('Post Plan'!$I$2:$I$348,B6,'Post Plan'!$M$2:$M$348) -> 4870 | S6: =SUMIF('Post Plan'!$I$2:$I$348,B6,'Post Plan'!$O$2:$O$348) -> 299.63782 | T6: =COUNTIFS('Post Plan'!$I$2:$I$348,B6,'Post Plan'!$B$2:$B$348,"Wave 1") -> 4 | U6: 2 | V6: Publish after its first 3 to 5 spokes so it launches with links to live content. | Y6: Not started | AA6: =COUNTIFS('Post Plan'!$I$2:$I$348,B6,'Post Plan'!$V$2:$V$348,"Published") -> 0
A7: 6 | B7: Lisbon | C7: City hub | D7: Europe | E7: Portugal | F7: New pillar to create | G7: Lisbon Travel Guide: Where to Eat, Drink and Explore | H7: lisbon travel guide | I7: 210 | J7: 16 | K7: =COUNTIF('Post Plan'!$I$2:$I$348,B7) -> 9 | L7: =COUNTIFS('Post Plan'!$I$2:$I$348,$B7,'Post Plan'!$J$2:$J$348,"Eat") -> 5 | M7: =COUNTIFS('Post Plan'!$I$2:$I$348,$B7,'Post Plan'!$J$2:$J$348,"Drink") -> 3 | N7: =COUNTIFS('Post Plan'!$I$2:$I$348,$B7,'Post Plan'!$J$2:$J$348,"Explore nearby") -> 1 | O7: =COUNTIFS('Post Plan'!$I$2:$I$348,$B7,'Post Plan'!$J$2:$J$348,"See & do") -> 0 | P7: =COUNTIFS('Post Plan'!$I$2:$I$348,$B7,'Post Plan'!$J$2:$J$348,"Beaches & islands") -> 0 | Q7: =COUNTIFS('Post Plan'!$I$2:$I$348,$B7,'Post Plan'!$J$2:$J$348,"Towns, villages & nature") -> 0 | R7: =SUMIF('Post Plan'!$I$2:$I$348,B7,'Post Plan'!$M$2:$M$348) -> 4950 | S7: =SUMIF('Post Plan'!$I$2:$I$348,B7,'Post Plan'!$O$2:$O$348) -> 290.03741 | T7: =COUNTIFS('Post Plan'!$I$2:$I$348,B7,'Post Plan'!$B$2:$B$348,"Wave 1") -> 3 | U7: 4 | V7: Publish after its first 3 to 5 spokes so it launches with links to live content. | Y7: Not started | AA7: =COUNTIFS('Post Plan'!$I$2:$I$348,B7,'Post Plan'!$V$2:$V$348,"Published") -> 0
A8: 7 | B8: Paris | C8: City hub | D8: Europe | E8: France | F8: New pillar to create | G8: Paris Travel Guide: Where to Eat, Drink and Explore | H8: paris travel guide | I8: 310 | J8: 35.5 | K8: =COUNTIF('Post Plan'!$I$2:$I$348,B8) -> 8 | L8: =COUNTIFS('Post Plan'!$I$2:$I$348,$B8,'Post Plan'!$J$2:$J$348,"Eat") -> 4 | M8: =COUNTIFS('Post Plan'!$I$2:$I$348,$B8,'Post Plan'!$J$2:$J$348,"Drink") -> 2 | N8: =COUNTIFS('Post Plan'!$I$2:$I$348,$B8,'Post Plan'!$J$2:$J$348,"Explore nearby") -> 1 | O8: =COUNTIFS('Post Plan'!$I$2:$I$348,$B8,'Post Plan'!$J$2:$J$348,"See & do") -> 1 | P8: =COUNTIFS('Post Plan'!$I$2:$I$348,$B8,'Post Plan'!$J$2:$J$348,"Beaches & islands") -> 0 | Q8: =COUNTIFS('Post Plan'!$I$2:$I$348,$B8,'Post Plan'!$J$2:$J$348,"Towns, villages & nature") -> 0 | R8: =SUMIF('Post Plan'!$I$2:$I$348,B8,'Post Plan'!$M$2:$M$348) -> 5420 | S8: =SUMIF('Post Plan'!$I$2:$I$348,B8,'Post Plan'!$O$2:$O$348) -> 285.72328 | T8: =COUNTIFS('Post Plan'!$I$2:$I$348,B8,'Post Plan'!$B$2:$B$348,"Wave 1") -> 5 | U8: 24 | V8: Publish after its first 3 to 5 spokes so it launches with links to live content. | Y8: Not started | AA8: =COUNTIFS('Post Plan'!$I$2:$I$348,B8,'Post Plan'!$V$2:$V$348,"Published") -> 0
A9: 8 | B9: Rome | C9: City hub | D9: Europe | E9: Italy | F9: New pillar to create | G9: Rome Travel Guide: Where to Eat, Drink and Explore | H9: rome travel guide | I9: 260 | J9: 24 | K9: =COUNTIF('Post Plan'!$I$2:$I$348,B9) -> 8 | L9: =COUNTIFS('Post Plan'!$I$2:$I$348,$B9,'Post Plan'!$J$2:$J$348,"Eat") -> 4 | M9: =COUNTIFS('Post Plan'!$I$2:$I$348,$B9,'Post Plan'!$J$2:$J$348,"Drink") -> 3 | N9: =COUNTIFS('Post Plan'!$I$2:$I$348,$B9,'Post Plan'!$J$2:$J$348,"Explore nearby") -> 0 | O9: =COUNTIFS('Post Plan'!$I$2:$I$348,$B9,'Post Plan'!$J$2:$J$348,"See & do") -> 1 | P9: =COUNTIFS('Post Plan'!$I$2:$I$348,$B9,'Post Plan'!$J$2:$J$348,"Beaches & islands") -> 0 | Q9: =COUNTIFS('Post Plan'!$I$2:$I$348,$B9,'Post Plan'!$J$2:$J$348,"Towns, villages & nature") -> 0 | R9: =SUMIF('Post Plan'!$I$2:$I$348,B9,'Post Plan'!$M$2:$M$348) -> 4630 | S9: =SUMIF('Post Plan'!$I$2:$I$348,B9,'Post Plan'!$O$2:$O$348) -> 276.29678 | T9: =COUNTIFS('Post Plan'!$I$2:$I$348,B9,'Post Plan'!$B$2:$B$348,"Wave 1") -> 5 | U9: 14 | V9: Publish after its first 3 to 5 spokes so it launches with links to live content. | Y9: Not started | AA9: =COUNTIFS('Post Plan'!$I$2:$I$348,B9,'Post Plan'!$V$2:$V$348,"Published") -> 0
A10: 9 | B10: Prague | C10: City hub | D10: Europe | E10: Europe | F10: New pillar to create | G10: Prague Travel Guide: Where to Eat, Drink and Explore | H10: prague travel guide | I10: 740 | J10: 34.2 | K10: =COUNTIF('Post Plan'!$I$2:$I$348,B10) -> 7 | L10: =COUNTIFS('Post Plan'!$I$2:$I$348,$B10,'Post Plan'!$J$2:$J$348,"Eat") -> 4 | M10: =COUNTIFS('Post Plan'!$I$2:$I$348,$B10,'Post Plan'!$J$2:$J$348,"Drink") -> 2 | N10: =COUNTIFS('Post Plan'!$I$2:$I$348,$B10,'Post Plan'!$J$2:$J$348,"Explore nearby") -> 1 | O10: =COUNTIFS('Post Plan'!$I$2:$I$348,$B10,'Post Plan'!$J$2:$J$348,"See & do") -> 0 | P10: =COUNTIFS('Post Plan'!$I$2:$I$348,$B10,'Post Plan'!$J$2:$J$348,"Beaches & islands") -> 0 | Q10: =COUNTIFS('Post Plan'!$I$2:$I$348,$B10,'Post Plan'!$J$2:$J$348,"Towns, villages & nature") -> 0 | R10: =SUMIF('Post Plan'!$I$2:$I$348,B10,'Post Plan'!$M$2:$M$348) -> 5160 | S10: =SUMIF('Post Plan'!$I$2:$I$348,B10,'Post Plan'!$O$2:$O$348) -> 266.59664 | T10: =COUNTIFS('Post Plan'!$I$2:$I$348,B10,'Post Plan'!$B$2:$B$348,"Wave 1") -> 5 | U10: 10 | V10: Publish after its first 3 to 5 spokes so it launches with links to live content. | Y10: Not started | AA10: =COUNTIFS('Post Plan'!$I$2:$I$348,B10,'Post Plan'!$V$2:$V$348,"Published") -> 0
A11: 10 | B11: Madrid | C11: City hub | D11: Europe | E11: Spain | F11: New pillar to create | G11: Madrid Travel Guide: Where to Eat, Drink and Explore | H11: madrid travel guide | I11: 590 | J11: 21.3 | K11: =COUNTIF('Post Plan'!$I$2:$I$348,B11) -> 6 | L11: =COUNTIFS('Post Plan'!$I$2:$I$348,$B11,'Post Plan'!$J$2:$J$348,"Eat") -> 3 | M11: =COUNTIFS('Post Plan'!$I$2:$I$348,$B11,'Post Plan'!$J$2:$J$348,"Drink") -> 2 | N11: =COUNTIFS('Post Plan'!$I$2:$I$348,$B11,'Post Plan'!$J$2:$J$348,"Explore nearby") -> 1 | O11: =COUNTIFS('Post Plan'!$I$2:$I$348,$B11,'Post Plan'!$J$2:$J$348,"See & do") -> 0 | P11: =COUNTIFS('Post Plan'!$I$2:$I$348,$B11,'Post Plan'!$J$2:$J$348,"Beaches & islands") -> 0 | Q11: =COUNTIFS('Post Plan'!$I$2:$I$348,$B11,'Post Plan'!$J$2:$J$348,"Towns, villages & nature") -> 0 | R11: =SUMIF('Post Plan'!$I$2:$I$348,B11,'Post Plan'!$M$2:$M$348) -> 4870 | S11: =SUMIF('Post Plan'!$I$2:$I$348,B11,'Post Plan'!$O$2:$O$348) -> 242.05915 | T11: =COUNTIFS('Post Plan'!$I$2:$I$348,B11,'Post Plan'!$B$2:$B$348,"Wave 1") -> 3 | U11: 13 | V11: Publish after its first 3 to 5 spokes so it launches with links to live content. | Y11: Not started | AA11: =COUNTIFS('Post Plan'!$I$2:$I$348,B11,'Post Plan'!$V$2:$V$348,"Published") -> 0
A12: 11 | B12: Edinburgh | C12: City hub | D12: UK | E12: Scotland | F12: Existing Edinburgh post | G12: Edinburgh Travel Guide: Where to Eat, Drink and Explore | H12: edinburgh travel guide | I12: 170 | J12: 25 | K12: =COUNTIF('Post Plan'!$I$2:$I$348,B12) -> 8 | L12: =COUNTIFS('Post Plan'!$I$2:$I$348,$B12,'Post Plan'!$J$2:$J$348,"Eat") -> 4 | M12: =COUNTIFS('Post Plan'!$I$2:$I$348,$B12,'Post Plan'!$J$2:$J$348,"Drink") -> 3 | N12: =COUNTIFS('Post Plan'!$I$2:$I$348,$B12,'Post Plan'!$J$2:$J$348,"Explore nearby") -> 1 | O12: =COUNTIFS('Post Plan'!$I$2:$I$348,$B12,'Post Plan'!$J$2:$J$348,"See & do") -> 0 | P12: =COUNTIFS('Post Plan'!$I$2:$I$348,$B12,'Post Plan'!$J$2:$J$348,"Beaches & islands") -> 0 | Q12: =COUNTIFS('Post Plan'!$I$2:$I$348,$B12,'Post Plan'!$J$2:$J$348,"Towns, villages & nature") -> 0 | R12: =SUMIF('Post Plan'!$I$2:$I$348,B12,'Post Plan'!$M$2:$M$348) -> 4330 | S12: =SUMIF('Post Plan'!$I$2:$I$348,B12,'Post Plan'!$O$2:$O$348) -> 232.91596 | T12: =COUNTIFS('Post Plan'!$I$2:$I$348,B12,'Post Plan'!$B$2:$B$348,"Wave 1") -> 2 | U12: 1 | V12: Upgrade the existing post into a hub: add a section per cluster linking to each spoke. | Y12: Not started | AA12: =COUNTIFS('Post Plan'!$I$2:$I$348,B12,'Post Plan'!$V$2:$V$348,"Published") -> 0
A13: 12 | B13: Osaka | C13: City hub | D13: Asia | E13: Japan | F13: New pillar to create | G13: Osaka Travel Guide: Where to Eat, Drink and Explore | H13: osaka travel guide | I13: 260 | J13: 35 | K13: =COUNTIF('Post Plan'!$I$2:$I$348,B13) -> 7 | L13: =COUNTIFS('Post Plan'!$I$2:$I$348,$B13,'Post Plan'!$J$2:$J$348,"Eat") -> 4 | M13: =COUNTIFS('Post Plan'!$I$2:$I$348,$B13,'Post Plan'!$J$2:$J$348,"Drink") -> 1 | N13: =COUNTIFS('Post Plan'!$I$2:$I$348,$B13,'Post Plan'!$J$2:$J$348,"Explore nearby") -> 1 | O13: =COUNTIFS('Post Plan'!$I$2:$I$348,$B13,'Post Plan'!$J$2:$J$348,"See & do") -> 1 | P13: =COUNTIFS('Post Plan'!$I$2:$I$348,$B13,'Post Plan'!$J$2:$J$348,"Beaches & islands") -> 0 | Q13: =COUNTIFS('Post Plan'!$I$2:$I$348,$B13,'Post Plan'!$J$2:$J$348,"Towns, villages & nature") -> 0 | R13: =SUMIF('Post Plan'!$I$2:$I$348,B13,'Post Plan'!$M$2:$M$348) -> 3650 | S13: =SUMIF('Post Plan'!$I$2:$I$348,B13,'Post Plan'!$O$2:$O$348) -> 212.70919 | T13: =COUNTIFS('Post Plan'!$I$2:$I$348,B13,'Post Plan'!$B$2:$B$348,"Wave 1") -> 2 | U13: 9 | V13: Publish after its first 3 to 5 spokes so it launches with links to live content. | Y13: Not started | AA13: =COUNTIFS('Post Plan'!$I$2:$I$348,B13,'Post Plan'!$V$2:$V$348,"Published") -> 0
A14: 13 | B14: Tokyo | C14: City hub | D14: Asia | E14: Japan | F14: Existing Tokyo post | G14: Tokyo Travel Guide: Where to Eat, Drink and Explore | H14: tokyo travel guide | K14: =COUNTIF('Post Plan'!$I$2:$I$348,B14) -> 6 | L14: =COUNTIFS('Post Plan'!$I$2:$I$348,$B14,'Post Plan'!$J$2:$J$348,"Eat") -> 4 | M14: =COUNTIFS('Post Plan'!$I$2:$I$348,$B14,'Post Plan'!$J$2:$J$348,"Drink") -> 1 | N14: =COUNTIFS('Post Plan'!$I$2:$I$348,$B14,'Post Plan'!$J$2:$J$348,"Explore nearby") -> 1 | O14: =COUNTIFS('Post Plan'!$I$2:$I$348,$B14,'Post Plan'!$J$2:$J$348,"See & do") -> 0 | P14: =COUNTIFS('Post Plan'!$I$2:$I$348,$B14,'Post Plan'!$J$2:$J$348,"Beaches & islands") -> 0 | Q14: =COUNTIFS('Post Plan'!$I$2:$I$348,$B14,'Post Plan'!$J$2:$J$348,"Towns, villages & nature") -> 0 | R14: =SUMIF('Post Plan'!$I$2:$I$348,B14,'Post Plan'!$M$2:$M$348) -> 3770 | S14: =SUMIF('Post Plan'!$I$2:$I$348,B14,'Post Plan'!$O$2:$O$348) -> 209.4802 | T14: =COUNTIFS('Post Plan'!$I$2:$I$348,B14,'Post Plan'!$B$2:$B$348,"Wave 1") -> 2 | U14: 3 | V14: Upgrade the existing post into a hub: add a section per cluster linking to each spoke. | Y14: Not started | AA14: =COUNTIFS('Post Plan'!$I$2:$I$348,B14,'Post Plan'!$V$2:$V$348,"Published") -> 0
A15: 14 | B15: Italy | C15: Country hub | D15: Europe | E15: Europe | F15: New pillar to create | G15: Italy Travel Guide: Where to Eat, Drink and Explore | H15: italy travel guide | K15: =COUNTIF('Post Plan'!$I$2:$I$348,B15) -> 10 | L15: =COUNTIFS('Post Plan'!$I$2:$I$348,$B15,'Post Plan'!$J$2:$J$348,"Eat") -> 2 | M15: =COUNTIFS('Post Plan'!$I$2:$I$348,$B15,'Post Plan'!$J$2:$J$348,"Drink") -> 0 | N15: =COUNTIFS('Post Plan'!$I$2:$I$348,$B15,'Post Plan'!$J$2:$J$348,"Explore nearby") -> 3 | O15: =COUNTIFS('Post Plan'!$I$2:$I$348,$B15,'Post Plan'!$J$2:$J$348,"See & do") -> 1 | P15: =COUNTIFS('Post Plan'!$I$2:$I$348,$B15,'Post Plan'!$J$2:$J$348,"Beaches & islands") -> 3 | Q15: =COUNTIFS('Post Plan'!$I$2:$I$348,$B15,'Post Plan'!$J$2:$J$348,"Towns, villages & nature") -> 1 | R15: =SUMIF('Post Plan'!$I$2:$I$348,B15,'Post Plan'!$M$2:$M$348) -> 3390 | S15: =SUMIF('Post Plan'!$I$2:$I$348,B15,'Post Plan'!$O$2:$O$348) -> 196.7776 | T15: =COUNTIFS('Post Plan'!$I$2:$I$348,B15,'Post Plan'!$B$2:$B$348,"Wave 1") -> 2 | U15: 30 | V15: Publish after its first 3 to 5 spokes so it launches with links to live content. Links down to child hubs: Florence, Naples, Rome, Venice. | Y15: Not started | AA15: =COUNTIFS('Post Plan'!$I$2:$I$348,B15,'Post Plan'!$V$2:$V$348,"Published") -> 0
A16: 15 | B16: Bangkok | C16: City hub | D16: Asia | E16: Thailand | F16: New pillar to create | G16: Bangkok Travel Guide: Where to Eat, Drink and Explore | H16: bangkok travel guide | I16: 370 | J16: 18.9 | K16: =COUNTIF('Post Plan'!$I$2:$I$348,B16) -> 7 | L16: =COUNTIFS('Post Plan'!$I$2:$I$348,$B16,'Post Plan'!$J$2:$J$348,"Eat") -> 5 | M16: =COUNTIFS('Post Plan'!$I$2:$I$348,$B16,'Post Plan'!$J$2:$J$348,"Drink") -> 1 | N16: =COUNTIFS('Post Plan'!$I$2:$I$348,$B16,'Post Plan'!$J$2:$J$348,"Explore nearby") -> 1 | O16: =COUNTIFS('Post Plan'!$I$2:$I$348,$B16,'Post Plan'!$J$2:$J$348,"See & do") -> 0 | P16: =COUNTIFS('Post Plan'!$I$2:$I$348,$B16,'Post Plan'!$J$2:$J$348,"Beaches & islands") -> 0 | Q16: =COUNTIFS('Post Plan'!$I$2:$I$348,$B16,'Post Plan'!$J$2:$J$348,"Towns, villages & nature") -> 0 | R16: =SUMIF('Post Plan'!$I$2:$I$348,B16,'Post Plan'!$M$2:$M$348) -> 3750 | S16: =SUMIF('Post Plan'!$I$2:$I$348,B16,'Post Plan'!$O$2:$O$348) -> 196.22604 | T16: =COUNTIFS('Post Plan'!$I$2:$I$348,B16,'Post Plan'!$B$2:$B$348,"Wave 1") -> 3 | U16: 40 | V16: Publish after its first 3 to 5 spokes so it launches with links to live content. | Y16: Not started | AA16: =COUNTIFS('Post Plan'!$I$2:$I$348,B16,'Post Plan'!$V$2:$V$348,"Published") -> 0
A17: 16 | B17: London | C17: City hub | D17: UK | E17: England | F17: Existing London post | G17: London Travel Guide: Where to Eat, Drink and Explore | H17: london travel guide | K17: =COUNTIF('Post Plan'!$I$2:$I$348,B17) -> 10 | L17: =COUNTIFS('Post Plan'!$I$2:$I$348,$B17,'Post Plan'!$J$2:$J$348,"Eat") -> 6 | M17: =COUNTIFS('Post Plan'!$I$2:$I$348,$B17,'Post Plan'!$J$2:$J$348,"Drink") -> 2 | N17: =COUNTIFS('Post Plan'!$I$2:$I$348,$B17,'Post Plan'!$J$2:$J$348,"Explore nearby") -> 2 | O17: =COUNTIFS('Post Plan'!$I$2:$I$348,$B17,'Post Plan'!$J$2:$J$348,"See & do") -> 0 | P17: =COUNTIFS('Post Plan'!$I$2:$I$348,$B17,'Post Plan'!$J$2:$J$348,"Beaches & islands") -> 0 | Q17: =COUNTIFS('Post Plan'!$I$2:$I$348,$B17,'Post Plan'!$J$2:$J$348,"Towns, villages & nature") -> 0 | R17: =SUMIF('Post Plan'!$I$2:$I$348,B17,'Post Plan'!$M$2:$M$348) -> 4310 | S17: =SUMIF('Post Plan'!$I$2:$I$348,B17,'Post Plan'!$O$2:$O$348) -> 196.08273 | T17: =COUNTIFS('Post Plan'!$I$2:$I$348,B17,'Post Plan'!$B$2:$B$348,"Wave 1") -> 2 | U17: 7 | V17: Upgrade the existing post into a hub: add a section per cluster linking to each spoke. | Y17: Not started | AA17: =COUNTIFS('Post Plan'!$I$2:$I$348,B17,'Post Plan'!$V$2:$V$348,"Published") -> 0
A18: 17 | B18: Barcelona | C18: City hub | D18: Europe | E18: Spain | F18: Existing Barcelona post | G18: Barcelona Travel Guide: Where to Eat, Drink and Explore | H18: barcelona travel guide | I18: 210 | J18: 14 | K18: =COUNTIF('Post Plan'!$I$2:$I$348,B18) -> 6 | L18: =COUNTIFS('Post Plan'!$I$2:$I$348,$B18,'Post Plan'!$J$2:$J$348,"Eat") -> 2 | M18: =COUNTIFS('Post Plan'!$I$2:$I$348,$B18,'Post Plan'!$J$2:$J$348,"Drink") -> 2 | N18: =COUNTIFS('Post Plan'!$I$2:$I$348,$B18,'Post Plan'!$J$2:$J$348,"Explore nearby") -> 1 | O18: =COUNTIFS('Post Plan'!$I$2:$I$348,$B18,'Post Plan'!$J$2:$J$348,"See & do") -> 0 | P18: =COUNTIFS('Post Plan'!$I$2:$I$348,$B18,'Post Plan'!$J$2:$J$348,"Beaches & islands") -> 1 | Q18: =COUNTIFS('Post Plan'!$I$2:$I$348,$B18,'Post Plan'!$J$2:$J$348,"Towns, villages & nature") -> 0 | R18: =SUMIF('Post Plan'!$I$2:$I$348,B18,'Post Plan'!$M$2:$M$348) -> 3580 | S18: =SUMIF('Post Plan'!$I$2:$I$348,B18,'Post Plan'!$O$2:$O$348) -> 188.62675 | T18: =COUNTIFS('Post Plan'!$I$2:$I$348,B18,'Post Plan'!$B$2:$B$348,"Wave 1") -> 2 | U18: 8 | V18: Upgrade the existing post into a hub: add a section per cluster linking to each spoke. | Y18: Not started | AA18: =COUNTIFS('Post Plan'!$I$2:$I$348,B18,'Post Plan'!$V$2:$V$348,"Published") -> 0
A19: 18 | B19: Florence | C19: City hub | D19: Europe | E19: Italy | F19: New pillar to create | G19: Florence Travel Guide: Where to Eat, Drink and Explore | H19: florence travel guide | I19: 350 | J19: 22.8 | K19: =COUNTIF('Post Plan'!$I$2:$I$348,B19) -> 5 | L19: =COUNTIFS('Post Plan'!$I$2:$I$348,$B19,'Post Plan'!$J$2:$J$348,"Eat") -> 3 | M19: =COUNTIFS('Post Plan'!$I$2:$I$348,$B19,'Post Plan'!$J$2:$J$348,"Drink") -> 2 | N19: =COUNTIFS('Post Plan'!$I$2:$I$348,$B19,'Post Plan'!$J$2:$J$348,"Explore nearby") -> 0 | O19: =COUNTIFS('Post Plan'!$I$2:$I$348,$B19,'Post Plan'!$J$2:$J$348,"See & do") -> 0 | P19: =COUNTIFS('Post Plan'!$I$2:$I$348,$B19,'Post Plan'!$J$2:$J$348,"Beaches & islands") -> 0 | Q19: =COUNTIFS('Post Plan'!$I$2:$I$348,$B19,'Post Plan'!$J$2:$J$348,"Towns, villages & nature") -> 0 | R19: =SUMIF('Post Plan'!$I$2:$I$348,B19,'Post Plan'!$M$2:$M$348) -> 3200 | S19: =SUMIF('Post Plan'!$I$2:$I$348,B19,'Post Plan'!$O$2:$O$348) -> 187.99695 | T19: =COUNTIFS('Post Plan'!$I$2:$I$348,B19,'Post Plan'!$B$2:$B$348,"Wave 1") -> 3 | U19: 29 | V19: Publish after its first 3 to 5 spokes so it launches with links to live content. | Y19: Not started | AA19: =COUNTIFS('Post Plan'!$I$2:$I$348,B19,'Post Plan'!$V$2:$V$348,"Published") -> 0
A20: 19 | B20: Venice | C20: City hub | D20: Europe | E20: Italy | F20: New pillar to create | G20: Venice Travel Guide: Where to Eat, Drink and Explore | H20: venice travel guide | I20: 460 | J20: 18.8 | K20: =COUNTIF('Post Plan'!$I$2:$I$348,B20) -> 6 | L20: =COUNTIFS('Post Plan'!$I$2:$I$348,$B20,'Post Plan'!$J$2:$J$348,"Eat") -> 4 | M20: =COUNTIFS('Post Plan'!$I$2:$I$348,$B20,'Post Plan'!$J$2:$J$348,"Drink") -> 0 | N20: =COUNTIFS('Post Plan'!$I$2:$I$348,$B20,'Post Plan'!$J$2:$J$348,"Explore nearby") -> 1 | O20: =COUNTIFS('Post Plan'!$I$2:$I$348,$B20,'Post Plan'!$J$2:$J$348,"See & do") -> 1 | P20: =COUNTIFS('Post Plan'!$I$2:$I$348,$B20,'Post Plan'!$J$2:$J$348,"Beaches & islands") -> 0 | Q20: =COUNTIFS('Post Plan'!$I$2:$I$348,$B20,'Post Plan'!$J$2:$J$348,"Towns, villages & nature") -> 0 | R20: =SUMIF('Post Plan'!$I$2:$I$348,B20,'Post Plan'!$M$2:$M$348) -> 3330 | S20: =SUMIF('Post Plan'!$I$2:$I$348,B20,'Post Plan'!$O$2:$O$348) -> 181.64038 | T20: =COUNTIFS('Post Plan'!$I$2:$I$348,B20,'Post Plan'!$B$2:$B$348,"Wave 1") -> 4 | U20: 55 | V20: Publish after its first 3 to 5 spokes so it launches with links to live content. | Y20: Not started | AA20: =COUNTIFS('Post Plan'!$I$2:$I$348,B20,'Post Plan'!$V$2:$V$348,"Published") -> 0
A21: 20 | B21: Amsterdam | C21: City hub | D21: Europe | E21: Europe | F21: Existing Amsterdam post | G21: Amsterdam Travel Guide: Where to Eat, Drink and Explore | H21: amsterdam travel guide | K21: =COUNTIF('Post Plan'!$I$2:$I$348,B21) -> 6 | L21: =COUNTIFS('Post Plan'!$I$2:$I$348,$B21,'Post Plan'!$J$2:$J$348,"Eat") -> 4 | M21: =COUNTIFS('Post Plan'!$I$2:$I$348,$B21,'Post Plan'!$J$2:$J$348,"Drink") -> 1 | N21: =COUNTIFS('Post Plan'!$I$2:$I$348,$B21,'Post Plan'!$J$2:$J$348,"Explore nearby") -> 1 | O21: =COUNTIFS('Post Plan'!$I$2:$I$348,$B21,'Post Plan'!$J$2:$J$348,"See & do") -> 0 | P21: =COUNTIFS('Post Plan'!$I$2:$I$348,$B21,'Post Plan'!$J$2:$J$348,"Beaches & islands") -> 0 | Q21: =COUNTIFS('Post Plan'!$I$2:$I$348,$B21,'Post Plan'!$J$2:$J$348,"Towns, villages & nature") -> 0 | R21: =SUMIF('Post Plan'!$I$2:$I$348,B21,'Post Plan'!$M$2:$M$348) -> 2930 | S21: =SUMIF('Post Plan'!$I$2:$I$348,B21,'Post Plan'!$O$2:$O$348) -> 164.30271 | T21: =COUNTIFS('Post Plan'!$I$2:$I$348,B21,'Post Plan'!$B$2:$B$348,"Wave 1") -> 2 | U21: 15 | V21: Upgrade the existing post into a hub: add a section per cluster linking to each spoke. | Y21: Not started | AA21: =COUNTIFS('Post Plan'!$I$2:$I$348,B21,'Post Plan'!$V$2:$V$348,"Published") -> 0
A22: 21 | B22: Singapore | C22: Country hub | D22: Asia | E22: Asia | F22: New pillar to create | G22: Singapore Travel Guide: Where to Eat, Drink and Explore | H22: singapore travel guide | I22: 460 | J22: 16 | K22: =COUNTIF('Post Plan'!$I$2:$I$348,B22) -> 7 | L22: =COUNTIFS('Post Plan'!$I$2:$I$348,$B22,'Post Plan'!$J$2:$J$348,"Eat") -> 5 | M22: =COUNTIFS('Post Plan'!$I$2:$I$348,$B22,'Post Plan'!$J$2:$J$348,"Drink") -> 1 | N22: =COUNTIFS('Post Plan'!$I$2:$I$348,$B22,'Post Plan'!$J$2:$J$348,"Explore nearby") -> 1 | O22: =COUNTIFS('Post Plan'!$I$2:$I$348,$B22,'Post Plan'!$J$2:$J$348,"See & do") -> 0 | P22: =COUNTIFS('Post Plan'!$I$2:$I$348,$B22,'Post Plan'!$J$2:$J$348,"Beaches & islands") -> 0 | Q22: =COUNTIFS('Post Plan'!$I$2:$I$348,$B22,'Post Plan'!$J$2:$J$348,"Towns, villages & nature") -> 0 | R22: =SUMIF('Post Plan'!$I$2:$I$348,B22,'Post Plan'!$M$2:$M$348) -> 2830 | S22: =SUMIF('Post Plan'!$I$2:$I$348,B22,'Post Plan'!$O$2:$O$348) -> 156.88792 | T22: =COUNTIFS('Post Plan'!$I$2:$I$348,B22,'Post Plan'!$B$2:$B$348,"Wave 1") -> 2 | U22: 22 | V22: Publish after its first 3 to 5 spokes so it launches with links to live content. | Y22: Not started | AA22: =COUNTIFS('Post Plan'!$I$2:$I$348,B22,'Post Plan'!$V$2:$V$348,"Published") -> 0
A23: 22 | B23: Nashville | C23: City hub | D23: North America | E23: USA | F23: New pillar to create | G23: Nashville Travel Guide: Where to Eat, Drink and Explore | H23: nashville travel guide | I23: 590 | J23: 13 | K23: =COUNTIF('Post Plan'!$I$2:$I$348,B23) -> 6 | L23: =COUNTIFS('Post Plan'!$I$2:$I$348,$B23,'Post Plan'!$J$2:$J$348,"Eat") -> 4 | M23: =COUNTIFS('Post Plan'!$I$2:$I$348,$B23,'Post Plan'!$J$2:$J$348,"Drink") -> 1 | N23: =COUNTIFS('Post Plan'!$I$2:$I$348,$B23,'Post Plan'!$J$2:$J$348,"Explore nearby") -> 0 | O23: =COUNTIFS('Post Plan'!$I$2:$I$348,$B23,'Post Plan'!$J$2:$J$348,"See & do") -> 1 | P23: =COUNTIFS('Post Plan'!$I$2:$I$348,$B23,'Post Plan'!$J$2:$J$348,"Beaches & islands") -> 0 | Q23: =COUNTIFS('Post Plan'!$I$2:$I$348,$B23,'Post Plan'!$J$2:$J$348,"Towns, villages & nature") -> 0 | R23: =SUMIF('Post Plan'!$I$2:$I$348,B23,'Post Plan'!$M$2:$M$348) -> 4220 | S23: =SUMIF('Post Plan'!$I$2:$I$348,B23,'Post Plan'!$O$2:$O$348) -> 149.94437 | T23: =COUNTIFS('Post Plan'!$I$2:$I$348,B23,'Post Plan'!$B$2:$B$348,"Wave 1") -> 2 | U23: 26 | V23: Publish after its first 3 to 5 spokes so it launches with links to live content. | Y23: Not started | AA23: =COUNTIFS('Post Plan'!$I$2:$I$348,B23,'Post Plan'!$V$2:$V$348,"Published") -> 0
A24: 23 | B24: Athens | C24: City hub | D24: Europe | E24: Greece | F24: Existing Athens post | G24: Athens Travel Guide: Where to Eat, Drink and Explore | H24: athens travel guide | K24: =COUNTIF('Post Plan'!$I$2:$I$348,B24) -> 6 | L24: =COUNTIFS('Post Plan'!$I$2:$I$348,$B24,'Post Plan'!$J$2:$J$348,"Eat") -> 3 | M24: =COUNTIFS('Post Plan'!$I$2:$I$348,$B24,'Post Plan'!$J$2:$J$348,"Drink") -> 2 | N24: =COUNTIFS('Post Plan'!$I$2:$I$348,$B24,'Post Plan'!$J$2:$J$348,"Explore nearby") -> 1 | O24: =COUNTIFS('Post Plan'!$I$2:$I$348,$B24,'Post Plan'!$J$2:$J$348,"See & do") -> 0 | P24: =COUNTIFS('Post Plan'!$I$2:$I$348,$B24,'Post Plan'!$J$2:$J$348,"Beaches & islands") -> 0 | Q24: =COUNTIFS('Post Plan'!$I$2:$I$348,$B24,'Post Plan'!$J$2:$J$348,"Towns, villages & nature") -> 0 | R24: =SUMIF('Post Plan'!$I$2:$I$348,B24,'Post Plan'!$M$2:$M$348) -> 2780 | S24: =SUMIF('Post Plan'!$I$2:$I$348,B24,'Post Plan'!$O$2:$O$348) -> 145.25901 | T24: =COUNTIFS('Post Plan'!$I$2:$I$348,B24,'Post Plan'!$B$2:$B$348,"Wave 1") -> 2 | U24: 50 | V24: Upgrade the existing post into a hub: add a section per cluster linking to each spoke. | Y24: Not started | AA24: =COUNTIFS('Post Plan'!$I$2:$I$348,B24,'Post Plan'!$V$2:$V$348,"Published") -> 0
A25: 24 | B25: Berlin | C25: City hub | D25: Europe | E25: Europe | F25: New pillar to create | G25: Berlin Travel Guide: Where to Eat, Drink and Explore | H25: berlin travel guide | I25: 490 | J25: 25.1 | K25: =COUNTIF('Post Plan'!$I$2:$I$348,B25) -> 3 | L25: =COUNTIFS('Post Plan'!$I$2:$I$348,$B25,'Post Plan'!$J$2:$J$348,"Eat") -> 2 | M25: =COUNTIFS('Post Plan'!$I$2:$I$348,$B25,'Post Plan'!$J$2:$J$348,"Drink") -> 1 | N25: =COUNTIFS('Post Plan'!$I$2:$I$348,$B25,'Post Plan'!$J$2:$J$348,"Explore nearby") -> 0 | O25: =COUNTIFS('Post Plan'!$I$2:$I$348,$B25,'Post Plan'!$J$2:$J$348,"See & do") -> 0 | P25: =COUNTIFS('Post Plan'!$I$2:$I$348,$B25,'Post Plan'!$J$2:$J$348,"Beaches & islands") -> 0 | Q25: =COUNTIFS('Post Plan'!$I$2:$I$348,$B25,'Post Plan'!$J$2:$J$348,"Towns, villages & nature") -> 0 | R25: =SUMIF('Post Plan'!$I$2:$I$348,B25,'Post Plan'!$M$2:$M$348) -> 2290 | S25: =SUMIF('Post Plan'!$I$2:$I$348,B25,'Post Plan'!$O$2:$O$348) -> 141.37392 | T25: =COUNTIFS('Post Plan'!$I$2:$I$348,B25,'Post Plan'!$B$2:$B$348,"Wave 1") -> 2 | U25: 5 | V25: Publish after its first 3 to 5 spokes so it launches with links to live content. | Y25: Not started | AA25: =COUNTIFS('Post Plan'!$I$2:$I$348,B25,'Post Plan'!$V$2:$V$348,"Published") -> 0
A26: 25 | B26: New York | C26: City hub | D26: North America | E26: USA | F26: Existing NYC post | G26: New York Travel Guide: Where to Eat, Drink and Explore | H26: new york travel guide | K26: =COUNTIF('Post Plan'!$I$2:$I$348,B26) -> 7 | L26: =COUNTIFS('Post Plan'!$I$2:$I$348,$B26,'Post Plan'!$J$2:$J$348,"Eat") -> 4 | M26: =COUNTIFS('Post Plan'!$I$2:$I$348,$B26,'Post Plan'!$J$2:$J$348,"Drink") -> 2 | N26: =COUNTIFS('Post Plan'!$I$2:$I$348,$B26,'Post Plan'!$J$2:$J$348,"Explore nearby") -> 1 | O26: =COUNTIFS('Post Plan'!$I$2:$I$348,$B26,'Post Plan'!$J$2:$J$348,"See & do") -> 0 | P26: =COUNTIFS('Post Plan'!$I$2:$I$348,$B26,'Post Plan'!$J$2:$J$348,"Beaches & islands") -> 0 | Q26: =COUNTIFS('Post Plan'!$I$2:$I$348,$B26,'Post Plan'!$J$2:$J$348,"Towns, villages & nature") -> 0 | R26: =SUMIF('Post Plan'!$I$2:$I$348,B26,'Post Plan'!$M$2:$M$348) -> 3570 | S26: =SUMIF('Post Plan'!$I$2:$I$348,B26,'Post Plan'!$O$2:$O$348) -> 135.21411 | T26: =COUNTIFS('Post Plan'!$I$2:$I$348,B26,'Post Plan'!$B$2:$B$348,"Wave 1") -> 2 | U26: 69 | V26: Upgrade the existing post into a hub: add a section per cluster linking to each spoke. | Y26: Not started | AA26: =COUNTIFS('Post Plan'!$I$2:$I$348,B26,'Post Plan'!$V$2:$V$348,"Published") -> 0
A27: 26 | B27: Budapest | C27: City hub | D27: Europe | E27: Europe | F27: New pillar to create | G27: Budapest Travel Guide: Where to Eat, Drink and Explore | H27: budapest travel guide | I27: 740 | J27: 9.1 | K27: =COUNTIF('Post Plan'!$I$2:$I$348,B27) -> 3 | L27: =COUNTIFS('Post Plan'!$I$2:$I$348,$B27,'Post Plan'!$J$2:$J$348,"Eat") -> 2 | M27: =COUNTIFS('Post Plan'!$I$2:$I$348,$B27,'Post Plan'!$J$2:$J$348,"Drink") -> 1 | N27: =COUNTIFS('Post Plan'!$I$2:$I$348,$B27,'Post Plan'!$J$2:$J$348,"Explore nearby") -> 0 | O27: =COUNTIFS('Post Plan'!$I$2:$I$348,$B27,'Post Plan'!$J$2:$J$348,"See & do") -> 0 | P27: =COUNTIFS('Post Plan'!$I$2:$I$348,$B27,'Post Plan'!$J$2:$J$348,"Beaches & islands") -> 0 | Q27: =COUNTIFS('Post Plan'!$I$2:$I$348,$B27,'Post Plan'!$J$2:$J$348,"Towns, villages & nature") -> 0 | R27: =SUMIF('Post Plan'!$I$2:$I$348,B27,'Post Plan'!$M$2:$M$348) -> 2160 | S27: =SUMIF('Post Plan'!$I$2:$I$348,B27,'Post Plan'!$O$2:$O$348) -> 127.39487 | T27: =COUNTIFS('Post Plan'!$I$2:$I$348,B27,'Post Plan'!$B$2:$B$348,"Wave 1") -> 2 | U27: 16 | V27: Publish after its first 3 to 5 spokes so it launches with links to live content. | Y27: Not started | AA27: =COUNTIFS('Post Plan'!$I$2:$I$348,B27,'Post Plan'!$V$2:$V$348,"Published") -> 0
A28: 27 | B28: Munich | C28: City hub | D28: Europe | E28: Europe | F28: New pillar to create | G28: Munich Travel Guide: Where to Eat, Drink and Explore | H28: munich travel guide | K28: =COUNTIF('Post Plan'!$I$2:$I$348,B28) -> 3 | L28: =COUNTIFS('Post Plan'!$I$2:$I$348,$B28,'Post Plan'!$J$2:$J$348,"Eat") -> 0 | M28: =COUNTIFS('Post Plan'!$I$2:$I$348,$B28,'Post Plan'!$J$2:$J$348,"Drink") -> 2 | N28: =COUNTIFS('Post Plan'!$I$2:$I$348,$B28,'Post Plan'!$J$2:$J$348,"Explore nearby") -> 1 | O28: =COUNTIFS('Post Plan'!$I$2:$I$348,$B28,'Post Plan'!$J$2:$J$348,"See & do") -> 0 | P28: =COUNTIFS('Post Plan'!$I$2:$I$348,$B28,'Post Plan'!$J$2:$J$348,"Beaches & islands") -> 0 | Q28: =COUNTIFS('Post Plan'!$I$2:$I$348,$B28,'Post Plan'!$J$2:$J$348,"Towns, villages & nature") -> 0 | R28: =SUMIF('Post Plan'!$I$2:$I$348,B28,'Post Plan'!$M$2:$M$348) -> 2410 | S28: =SUMIF('Post Plan'!$I$2:$I$348,B28,'Post Plan'!$O$2:$O$348) -> 126.87103 | T28: =COUNTIFS('Post Plan'!$I$2:$I$348,B28,'Post Plan'!$B$2:$B$348,"Wave 1") -> 2 | U28: 27 | V28: Publish after its first 3 to 5 spokes so it launches with links to live content. | Y28: Not started | AA28: =COUNTIFS('Post Plan'!$I$2:$I$348,B28,'Post Plan'!$V$2:$V$348,"Published") -> 0
A29: 28 | B29: New Orleans | C29: City hub | D29: North America | E29: USA | F29: New pillar to create | G29: New Orleans Travel Guide: Where to Eat, Drink and Explore | H29: new orleans travel guide | K29: =COUNTIF('Post Plan'!$I$2:$I$348,B29) -> 8 | L29: =COUNTIFS('Post Plan'!$I$2:$I$348,$B29,'Post Plan'!$J$2:$J$348,"Eat") -> 5 | M29: =COUNTIFS('Post Plan'!$I$2:$I$348,$B29,'Post Plan'!$J$2:$J$348,"Drink") -> 2 | N29: =COUNTIFS('Post Plan'!$I$2:$I$348,$B29,'Post Plan'!$J$2:$J$348,"Explore nearby") -> 0 | O29: =COUNTIFS('Post Plan'!$I$2:$I$348,$B29,'Post Plan'!$J$2:$J$348,"See & do") -> 1 | P29: =COUNTIFS('Post Plan'!$I$2:$I$348,$B29,'Post Plan'!$J$2:$J$348,"Beaches & islands") -> 0 | Q29: =COUNTIFS('Post Plan'!$I$2:$I$348,$B29,'Post Plan'!$J$2:$J$348,"Towns, villages & nature") -> 0 | R29: =SUMIF('Post Plan'!$I$2:$I$348,B29,'Post Plan'!$M$2:$M$348) -> 2960 | S29: =SUMIF('Post Plan'!$I$2:$I$348,B29,'Post Plan'!$O$2:$O$348) -> 126.40813 | T29: =COUNTIFS('Post Plan'!$I$2:$I$348,B29,'Post Plan'!$B$2:$B$348,"Wave 1") -> 0 | U29: 113 | V29: Publish after its first 3 to 5 spokes so it launches with links to live content. | Y29: Not started | AA29: =COUNTIFS('Post Plan'!$I$2:$I$348,B29,'Post Plan'!$V$2:$V$348,"Published") -> 0
A30: 29 | B30: Dublin | C30: City hub | D30: Europe | E30: Ireland | F30: New pillar to create | G30: Dublin Travel Guide: Where to Eat, Drink and Explore | H30: dublin travel guide | I30: 370 | J30: 31.2 | K30: =COUNTIF('Post Plan'!$I$2:$I$348,B30) -> 4 | L30: =COUNTIFS('Post Plan'!$I$2:$I$348,$B30,'Post Plan'!$J$2:$J$348,"Eat") -> 3 | M30: =COUNTIFS('Post Plan'!$I$2:$I$348,$B30,'Post Plan'!$J$2:$J$348,"Drink") -> 1 | N30: =COUNTIFS('Post Plan'!$I$2:$I$348,$B30,'Post Plan'!$J$2:$J$348,"Explore nearby") -> 0 | O30: =COUNTIFS('Post Plan'!$I$2:$I$348,$B30,'Post Plan'!$J$2:$J$348,"See & do") -> 0 | P30: =COUNTIFS('Post Plan'!$I$2:$I$348,$B30,'Post Plan'!$J$2:$J$348,"Beaches & islands") -> 0 | Q30: =COUNTIFS('Post Plan'!$I$2:$I$348,$B30,'Post Plan'!$J$2:$J$348,"Towns, villages & nature") -> 0 | R30: =SUMIF('Post Plan'!$I$2:$I$348,B30,'Post Plan'!$M$2:$M$348) -> 2390 | S30: =SUMIF('Post Plan'!$I$2:$I$348,B30,'Post Plan'!$O$2:$O$348) -> 117.22382 | T30: =COUNTIFS('Post Plan'!$I$2:$I$348,B30,'Post Plan'!$B$2:$B$348,"Wave 1") -> 1 | U30: 77 | V30: Publish after its first 3 to 5 spokes so it launches with links to live content. | Y30: Not started | AA30: =COUNTIFS('Post Plan'!$I$2:$I$348,B30,'Post Plan'!$V$2:$V$348,"Published") -> 0
A31: 30 | B31: Kyoto | C31: City hub | D31: Asia | E31: Japan | F31: New pillar to create | G31: Kyoto Travel Guide: Where to Eat, Drink and Explore | H31: kyoto travel guide | I31: 430 | J31: 33.2 | K31: =COUNTIF('Post Plan'!$I$2:$I$348,B31) -> 4 | L31: =COUNTIFS('Post Plan'!$I$2:$I$348,$B31,'Post Plan'!$J$2:$J$348,"Eat") -> 2 | M31: =COUNTIFS('Post Plan'!$I$2:$I$348,$B31,'Post Plan'!$J$2:$J$348,"Drink") -> 0 | N31: =COUNTIFS('Post Plan'!$I$2:$I$348,$B31,'Post Plan'!$J$2:$J$348,"Explore nearby") -> 1 | O31: =COUNTIFS('Post Plan'!$I$2:$I$348,$B31,'Post Plan'!$J$2:$J$348,"See & do") -> 1 | P31: =COUNTIFS('Post Plan'!$I$2:$I$348,$B31,'Post Plan'!$J$2:$J$348,"Beaches & islands") -> 0 | Q31: =COUNTIFS('Post Plan'!$I$2:$I$348,$B31,'Post Plan'!$J$2:$J$348,"Towns, villages & nature") -> 0 | R31: =SUMIF('Post Plan'!$I$2:$I$348,B31,'Post Plan'!$M$2:$M$348) -> 2720 | S31: =SUMIF('Post Plan'!$I$2:$I$348,B31,'Post Plan'!$O$2:$O$348) -> 117.13136 | T31: =COUNTIFS('Post Plan'!$I$2:$I$348,B31,'Post Plan'!$B$2:$B$348,"Wave 1") -> 1 | U31: 12 | V31: Publish after its first 3 to 5 spokes so it launches with links to live content. | Y31: Not started | AA31: =COUNTIFS('Post Plan'!$I$2:$I$348,B31,'Post Plan'!$V$2:$V$348,"Published") -> 0
A32: 31 | B32: Asia | C32: Region hub | D32: Asia | E32: Home / Destinations | F32: New pillar to create | G32: Asia Travel Guide: Best Places to Eat, Drink and Explore | H32: asia travel guide | K32: =COUNTIF('Post Plan'!$I$2:$I$348,B32) -> 6 | L32: =COUNTIFS('Post Plan'!$I$2:$I$348,$B32,'Post Plan'!$J$2:$J$348,"Eat") -> 2 | M32: =COUNTIFS('Post Plan'!$I$2:$I$348,$B32,'Post Plan'!$J$2:$J$348,"Drink") -> 0 | N32: =COUNTIFS('Post Plan'!$I$2:$I$348,$B32,'Post Plan'!$J$2:$J$348,"Explore nearby") -> 1 | O32: =COUNTIFS('Post Plan'!$I$2:$I$348,$B32,'Post Plan'!$J$2:$J$348,"See & do") -> 0 | P32: =COUNTIFS('Post Plan'!$I$2:$I$348,$B32,'Post Plan'!$J$2:$J$348,"Beaches & islands") -> 3 | Q32: =COUNTIFS('Post Plan'!$I$2:$I$348,$B32,'Post Plan'!$J$2:$J$348,"Towns, villages & nature") -> 0 | R32: =SUMIF('Post Plan'!$I$2:$I$348,B32,'Post Plan'!$M$2:$M$348) -> 2780 | S32: =SUMIF('Post Plan'!$I$2:$I$348,B32,'Post Plan'!$O$2:$O$348) -> 116.55839 | T32: =COUNTIFS('Post Plan'!$I$2:$I$348,B32,'Post Plan'!$B$2:$B$348,"Wave 1") -> 0 | U32: 117 | V32: Publish after its first 3 to 5 spokes so it launches with links to live content. Links down to child hubs: Hong Kong, Japan, Seoul, Singapore, Thailand, Vietnam. | Y32: Not started | AA32: =COUNTIFS('Post Plan'!$I$2:$I$348,B32,'Post Plan'!$V$2:$V$348,"Published") -> 0
